Scheduler started @ 2021-06-26 15:39:51,989
Scheduler started @ 2021-06-29 00:19:31,203
No error handlers are registered, logging exception. @ 2021-06-29 00:20:45,763
Traceback (most recent call last):
  File "C:\Users\Vincent\AppData\Local\Programs\Python\Python39\lib\site-packages\telegram\ext\dispatcher.py", line 555, in process_update
    handler.handle_update(update, self, check, context)
  File "C:\Users\Vincent\AppData\Local\Programs\Python\Python39\lib\site-packages\telegram\ext\handler.py", line 198, in handle_update
    return self.callback(update, context)
  File "C:\Users\Vincent\Documents\GitHub\cloudRPC\Cloud_Prototype\tg.py", line 57, in getLog
    response = requests.post(send_file,  files=files)
  File "C:\Users\Vincent\AppData\Local\Programs\Python\Python39\lib\site-packages\requests\api.py", line 119, in post
    return request('post', url, data=data, json=json, **kwargs)
  File "C:\Users\Vincent\AppData\Local\Programs\Python\Python39\lib\site-packages\requests\api.py", line 61, in request
    return session.request(method=method, url=url, **kwargs)
  File "C:\Users\Vincent\AppData\Local\Programs\Python\Python39\lib\site-packages\requests\sessions.py", line 528, in request
    prep = self.prepare_request(req)
  File "C:\Users\Vincent\AppData\Local\Programs\Python\Python39\lib\site-packages\requests\sessions.py", line 456, in prepare_request
    p.prepare(
  File "C:\Users\Vincent\AppData\Local\Programs\Python\Python39\lib\site-packages\requests\models.py", line 319, in prepare
    self.prepare_body(data, files, json)
  File "C:\Users\Vincent\AppData\Local\Programs\Python\Python39\lib\site-packages\requests\models.py", line 507, in prepare_body
    (body, content_type) = self._encode_files(files, data)
  File "C:\Users\Vincent\AppData\Local\Programs\Python\Python39\lib\site-packages\requests\models.py", line 159, in _encode_files
    fdata = fp.read()
  File "C:\Users\Vincent\AppData\Local\Programs\Python\Python39\lib\encodings\cp1252.py", line 23, in decode
    return codecs.charmap_decode(input,self.errors,decoding_table)[0]
UnicodeDecodeError: 'charmap' codec can't decode byte 0x9d in position 141: character maps to <undefined>
No error handlers are registered, logging exception. @ 2021-06-29 00:21:32,160
Traceback (most recent call last):
  File "C:\Users\Vincent\AppData\Local\Programs\Python\Python39\lib\site-packages\telegram\ext\dispatcher.py", line 555, in process_update
    handler.handle_update(update, self, check, context)
  File "C:\Users\Vincent\AppData\Local\Programs\Python\Python39\lib\site-packages\telegram\ext\handler.py", line 198, in handle_update
    return self.callback(update, context)
  File "C:\Users\Vincent\Documents\GitHub\cloudRPC\Cloud_Prototype\tg.py", line 57, in getLog
    response = requests.post(send_file,  files=files)
  File "C:\Users\Vincent\AppData\Local\Programs\Python\Python39\lib\site-packages\requests\api.py", line 119, in post
    return request('post', url, data=data, json=json, **kwargs)
  File "C:\Users\Vincent\AppData\Local\Programs\Python\Python39\lib\site-packages\requests\api.py", line 61, in request
    return session.request(method=method, url=url, **kwargs)
  File "C:\Users\Vincent\AppData\Local\Programs\Python\Python39\lib\site-packages\requests\sessions.py", line 528, in request
    prep = self.prepare_request(req)
  File "C:\Users\Vincent\AppData\Local\Programs\Python\Python39\lib\site-packages\requests\sessions.py", line 456, in prepare_request
    p.prepare(
  File "C:\Users\Vincent\AppData\Local\Programs\Python\Python39\lib\site-packages\requests\models.py", line 319, in prepare
    self.prepare_body(data, files, json)
  File "C:\Users\Vincent\AppData\Local\Programs\Python\Python39\lib\site-packages\requests\models.py", line 507, in prepare_body
    (body, content_type) = self._encode_files(files, data)
  File "C:\Users\Vincent\AppData\Local\Programs\Python\Python39\lib\site-packages\requests\models.py", line 159, in _encode_files
    fdata = fp.read()
  File "C:\Users\Vincent\AppData\Local\Programs\Python\Python39\lib\encodings\cp1252.py", line 23, in decode
    return codecs.charmap_decode(input,self.errors,decoding_table)[0]
UnicodeDecodeError: 'charmap' codec can't decode byte 0x9d in position 141: character maps to <undefined>
No error handlers are registered, logging exception. @ 2021-06-29 00:21:50,514
Traceback (most recent call last):
  File "C:\Users\Vincent\AppData\Local\Programs\Python\Python39\lib\site-packages\telegram\ext\dispatcher.py", line 555, in process_update
    handler.handle_update(update, self, check, context)
  File "C:\Users\Vincent\AppData\Local\Programs\Python\Python39\lib\site-packages\telegram\ext\handler.py", line 198, in handle_update
    return self.callback(update, context)
  File "C:\Users\Vincent\Documents\GitHub\cloudRPC\Cloud_Prototype\tg.py", line 57, in getLog
    response = requests.post(send_file,  files=files)
  File "C:\Users\Vincent\AppData\Local\Programs\Python\Python39\lib\site-packages\requests\api.py", line 119, in post
    return request('post', url, data=data, json=json, **kwargs)
  File "C:\Users\Vincent\AppData\Local\Programs\Python\Python39\lib\site-packages\requests\api.py", line 61, in request
    return session.request(method=method, url=url, **kwargs)
  File "C:\Users\Vincent\AppData\Local\Programs\Python\Python39\lib\site-packages\requests\sessions.py", line 528, in request
    prep = self.prepare_request(req)
  File "C:\Users\Vincent\AppData\Local\Programs\Python\Python39\lib\site-packages\requests\sessions.py", line 456, in prepare_request
    p.prepare(
  File "C:\Users\Vincent\AppData\Local\Programs\Python\Python39\lib\site-packages\requests\models.py", line 319, in prepare
    self.prepare_body(data, files, json)
  File "C:\Users\Vincent\AppData\Local\Programs\Python\Python39\lib\site-packages\requests\models.py", line 507, in prepare_body
    (body, content_type) = self._encode_files(files, data)
  File "C:\Users\Vincent\AppData\Local\Programs\Python\Python39\lib\site-packages\requests\models.py", line 159, in _encode_files
    fdata = fp.read()
  File "C:\Users\Vincent\AppData\Local\Programs\Python\Python39\lib\encodings\cp1252.py", line 23, in decode
    return codecs.charmap_decode(input,self.errors,decoding_table)[0]
UnicodeDecodeError: 'charmap' codec can't decode byte 0x9d in position 141: character maps to <undefined>
No error handlers are registered, logging exception. @ 2021-06-29 00:22:46,416
Traceback (most recent call last):
  File "C:\Users\Vincent\AppData\Local\Programs\Python\Python39\lib\site-packages\telegram\ext\dispatcher.py", line 555, in process_update
    handler.handle_update(update, self, check, context)
  File "C:\Users\Vincent\AppData\Local\Programs\Python\Python39\lib\site-packages\telegram\ext\handler.py", line 198, in handle_update
    return self.callback(update, context)
  File "C:\Users\Vincent\Documents\GitHub\cloudRPC\Cloud_Prototype\tg.py", line 57, in getLog
    response = requests.post(send_file,  files=files)
  File "C:\Users\Vincent\AppData\Local\Programs\Python\Python39\lib\site-packages\requests\api.py", line 119, in post
    return request('post', url, data=data, json=json, **kwargs)
  File "C:\Users\Vincent\AppData\Local\Programs\Python\Python39\lib\site-packages\requests\api.py", line 61, in request
    return session.request(method=method, url=url, **kwargs)
  File "C:\Users\Vincent\AppData\Local\Programs\Python\Python39\lib\site-packages\requests\sessions.py", line 528, in request
    prep = self.prepare_request(req)
  File "C:\Users\Vincent\AppData\Local\Programs\Python\Python39\lib\site-packages\requests\sessions.py", line 456, in prepare_request
    p.prepare(
  File "C:\Users\Vincent\AppData\Local\Programs\Python\Python39\lib\site-packages\requests\models.py", line 319, in prepare
    self.prepare_body(data, files, json)
  File "C:\Users\Vincent\AppData\Local\Programs\Python\Python39\lib\site-packages\requests\models.py", line 507, in prepare_body
    (body, content_type) = self._encode_files(files, data)
  File "C:\Users\Vincent\AppData\Local\Programs\Python\Python39\lib\site-packages\requests\models.py", line 159, in _encode_files
    fdata = fp.read()
  File "C:\Users\Vincent\AppData\Local\Programs\Python\Python39\lib\encodings\cp1252.py", line 23, in decode
    return codecs.charmap_decode(input,self.errors,decoding_table)[0]
UnicodeDecodeError: 'charmap' codec can't decode byte 0x8d in position 195: character maps to <undefined>
Received signal 2 (SIGINT), stopping... @ 2021-06-29 00:23:37,007
Scheduler has been shut down @ 2021-06-29 00:23:37,007
Scheduler started @ 2021-06-29 00:23:51,050
No error handlers are registered, logging exception. @ 2021-06-29 00:23:56,864
Traceback (most recent call last):
  File "C:\Users\Vincent\AppData\Local\Programs\Python\Python39\lib\site-packages\telegram\ext\dispatcher.py", line 555, in process_update
    handler.handle_update(update, self, check, context)
  File "C:\Users\Vincent\AppData\Local\Programs\Python\Python39\lib\site-packages\telegram\ext\handler.py", line 198, in handle_update
    return self.callback(update, context)
  File "C:\Users\Vincent\Documents\GitHub\cloudRPC\Cloud_Prototype\tg.py", line 57, in getLog
    response = requests.post(send_file,  files=files)
  File "C:\Users\Vincent\AppData\Local\Programs\Python\Python39\lib\site-packages\requests\api.py", line 119, in post
    return request('post', url, data=data, json=json, **kwargs)
  File "C:\Users\Vincent\AppData\Local\Programs\Python\Python39\lib\site-packages\requests\api.py", line 61, in request
    return session.request(method=method, url=url, **kwargs)
  File "C:\Users\Vincent\AppData\Local\Programs\Python\Python39\lib\site-packages\requests\sessions.py", line 528, in request
    prep = self.prepare_request(req)
  File "C:\Users\Vincent\AppData\Local\Programs\Python\Python39\lib\site-packages\requests\sessions.py", line 456, in prepare_request
    p.prepare(
  File "C:\Users\Vincent\AppData\Local\Programs\Python\Python39\lib\site-packages\requests\models.py", line 319, in prepare
    self.prepare_body(data, files, json)
  File "C:\Users\Vincent\AppData\Local\Programs\Python\Python39\lib\site-packages\requests\models.py", line 507, in prepare_body
    (body, content_type) = self._encode_files(files, data)
  File "C:\Users\Vincent\AppData\Local\Programs\Python\Python39\lib\site-packages\requests\models.py", line 159, in _encode_files
    fdata = fp.read()
  File "C:\Users\Vincent\AppData\Local\Programs\Python\Python39\lib\encodings\cp1252.py", line 23, in decode
    return codecs.charmap_decode(input,self.errors,decoding_table)[0]
UnicodeDecodeError: 'charmap' codec can't decode byte 0x8d in position 195: character maps to <undefined>
No error handlers are registered, logging exception. @ 2021-06-29 00:24:22,126
Traceback (most recent call last):
  File "C:\Users\Vincent\AppData\Local\Programs\Python\Python39\lib\site-packages\telegram\ext\dispatcher.py", line 555, in process_update
    handler.handle_update(update, self, check, context)
  File "C:\Users\Vincent\AppData\Local\Programs\Python\Python39\lib\site-packages\telegram\ext\handler.py", line 198, in handle_update
    return self.callback(update, context)
  File "C:\Users\Vincent\Documents\GitHub\cloudRPC\Cloud_Prototype\tg.py", line 57, in getLog
    response = requests.post(send_file,  files=files)
  File "C:\Users\Vincent\AppData\Local\Programs\Python\Python39\lib\site-packages\requests\api.py", line 119, in post
    return request('post', url, data=data, json=json, **kwargs)
  File "C:\Users\Vincent\AppData\Local\Programs\Python\Python39\lib\site-packages\requests\api.py", line 61, in request
    return session.request(method=method, url=url, **kwargs)
  File "C:\Users\Vincent\AppData\Local\Programs\Python\Python39\lib\site-packages\requests\sessions.py", line 528, in request
    prep = self.prepare_request(req)
  File "C:\Users\Vincent\AppData\Local\Programs\Python\Python39\lib\site-packages\requests\sessions.py", line 456, in prepare_request
    p.prepare(
  File "C:\Users\Vincent\AppData\Local\Programs\Python\Python39\lib\site-packages\requests\models.py", line 319, in prepare
    self.prepare_body(data, files, json)
  File "C:\Users\Vincent\AppData\Local\Programs\Python\Python39\lib\site-packages\requests\models.py", line 507, in prepare_body
    (body, content_type) = self._encode_files(files, data)
  File "C:\Users\Vincent\AppData\Local\Programs\Python\Python39\lib\site-packages\requests\models.py", line 159, in _encode_files
    fdata = fp.read()
  File "C:\Users\Vincent\AppData\Local\Programs\Python\Python39\lib\encodings\cp1252.py", line 23, in decode
    return codecs.charmap_decode(input,self.errors,decoding_table)[0]
UnicodeDecodeError: 'charmap' codec can't decode byte 0x8f in position 203: character maps to <undefined>
Received signal 2 (SIGINT), stopping... @ 2021-06-29 00:24:47,739
Scheduler has been shut down @ 2021-06-29 00:24:47,739
Exiting immediately! @ 2021-06-29 00:24:52,658
Scheduler started @ 2021-06-29 08:52:53,058
No error handlers are registered, logging exception. @ 2021-06-29 08:53:28,399
Traceback (most recent call last):
  File "C:\Users\Vincent\AppData\Local\Programs\Python\Python39\lib\site-packages\telegram\ext\dispatcher.py", line 555, in process_update
    handler.handle_update(update, self, check, context)
  File "C:\Users\Vincent\AppData\Local\Programs\Python\Python39\lib\site-packages\telegram\ext\handler.py", line 198, in handle_update
    return self.callback(update, context)
  File "C:\Users\Vincent\Documents\GitHub\cloudRPC\Cloud_Prototype\tg.py", line 32, in getLog
    response = stub.getLogs(assignment_prototype_pb2.RequestLog(types=3))
  File "C:\Users\Vincent\AppData\Local\Programs\Python\Python39\lib\site-packages\grpc\_channel.py", line 946, in __call__
    return _end_unary_response_blocking(state, call, False, None)
  File "C:\Users\Vincent\AppData\Local\Programs\Python\Python39\lib\site-packages\grpc\_channel.py", line 849, in _end_unary_response_blocking
    raise _InactiveRpcError(state)
grpc._channel._InactiveRpcError: <_InactiveRpcError of RPC that terminated with:
	status = StatusCode.UNAVAILABLE
	details = "failed to connect to all addresses"
	debug_error_string = "{"created":"@1624928008.397000000","description":"Failed to pick subchannel","file":"src/core/ext/filters/client_channel/client_channel.cc","file_line":3009,"referenced_errors":[{"created":"@1624928008.397000000","description":"failed to connect to all addresses","file":"src/core/ext/filters/client_channel/lb_policy/pick_first/pick_first.cc","file_line":398,"grpc_status":14}]}"
>
No error handlers are registered, logging exception. @ 2021-06-29 08:53:59,028
Traceback (most recent call last):
  File "C:\Users\Vincent\AppData\Local\Programs\Python\Python39\lib\site-packages\telegram\ext\dispatcher.py", line 555, in process_update
    handler.handle_update(update, self, check, context)
  File "C:\Users\Vincent\AppData\Local\Programs\Python\Python39\lib\site-packages\telegram\ext\handler.py", line 198, in handle_update
    return self.callback(update, context)
  File "C:\Users\Vincent\Documents\GitHub\cloudRPC\Cloud_Prototype\tg.py", line 32, in getLog
    response = stub.getLogs(assignment_prototype_pb2.RequestLog(types=3))
  File "C:\Users\Vincent\AppData\Local\Programs\Python\Python39\lib\site-packages\grpc\_channel.py", line 946, in __call__
    return _end_unary_response_blocking(state, call, False, None)
  File "C:\Users\Vincent\AppData\Local\Programs\Python\Python39\lib\site-packages\grpc\_channel.py", line 849, in _end_unary_response_blocking
    raise _InactiveRpcError(state)
grpc._channel._InactiveRpcError: <_InactiveRpcError of RPC that terminated with:
	status = StatusCode.UNAVAILABLE
	details = "failed to connect to all addresses"
	debug_error_string = "{"created":"@1624928039.027000000","description":"Failed to pick subchannel","file":"src/core/ext/filters/client_channel/client_channel.cc","file_line":3009,"referenced_errors":[{"created":"@1624928039.027000000","description":"failed to connect to all addresses","file":"src/core/ext/filters/client_channel/lb_policy/pick_first/pick_first.cc","file_line":398,"grpc_status":14}]}"
>
No error handlers are registered, logging exception. @ 2021-06-29 08:54:54,985
Traceback (most recent call last):
  File "C:\Users\Vincent\AppData\Local\Programs\Python\Python39\lib\site-packages\telegram\ext\dispatcher.py", line 555, in process_update
    handler.handle_update(update, self, check, context)
  File "C:\Users\Vincent\AppData\Local\Programs\Python\Python39\lib\site-packages\telegram\ext\handler.py", line 198, in handle_update
    return self.callback(update, context)
  File "C:\Users\Vincent\Documents\GitHub\cloudRPC\Cloud_Prototype\tg.py", line 32, in getLog
    response = stub.getLogs(assignment_prototype_pb2.RequestLog(types=3))
  File "C:\Users\Vincent\AppData\Local\Programs\Python\Python39\lib\site-packages\grpc\_channel.py", line 946, in __call__
    return _end_unary_response_blocking(state, call, False, None)
  File "C:\Users\Vincent\AppData\Local\Programs\Python\Python39\lib\site-packages\grpc\_channel.py", line 849, in _end_unary_response_blocking
    raise _InactiveRpcError(state)
grpc._channel._InactiveRpcError: <_InactiveRpcError of RPC that terminated with:
	status = StatusCode.UNAVAILABLE
	details = "failed to connect to all addresses"
	debug_error_string = "{"created":"@1624928094.985000000","description":"Failed to pick subchannel","file":"src/core/ext/filters/client_channel/client_channel.cc","file_line":3009,"referenced_errors":[{"created":"@1624928094.985000000","description":"failed to connect to all addresses","file":"src/core/ext/filters/client_channel/lb_policy/pick_first/pick_first.cc","file_line":398,"grpc_status":14}]}"
>
No error handlers are registered, logging exception. @ 2021-06-29 10:03:59,026
Traceback (most recent call last):
  File "C:\Users\Vincent\AppData\Local\Programs\Python\Python39\lib\site-packages\telegram\ext\dispatcher.py", line 555, in process_update
    handler.handle_update(update, self, check, context)
  File "C:\Users\Vincent\AppData\Local\Programs\Python\Python39\lib\site-packages\telegram\ext\handler.py", line 198, in handle_update
    return self.callback(update, context)
  File "C:\Users\Vincent\Documents\GitHub\cloudRPC\Cloud_Prototype\tg.py", line 32, in getLog
    stub = assignment_prototype_pb2_grpc.communicatorStub(channel)
  File "C:\Users\Vincent\AppData\Local\Programs\Python\Python39\lib\site-packages\grpc\_channel.py", line 946, in __call__
    return _end_unary_response_blocking(state, call, False, None)
  File "C:\Users\Vincent\AppData\Local\Programs\Python\Python39\lib\site-packages\grpc\_channel.py", line 849, in _end_unary_response_blocking
    raise _InactiveRpcError(state)
grpc._channel._InactiveRpcError: <_InactiveRpcError of RPC that terminated with:
	status = StatusCode.UNAVAILABLE
	details = "failed to connect to all addresses"
	debug_error_string = "{"created":"@1624932239.025000000","description":"Failed to pick subchannel","file":"src/core/ext/filters/client_channel/client_channel.cc","file_line":3009,"referenced_errors":[{"created":"@1624932239.025000000","description":"failed to connect to all addresses","file":"src/core/ext/filters/client_channel/lb_policy/pick_first/pick_first.cc","file_line":398,"grpc_status":14}]}"
>
Received signal 2 (SIGINT), stopping... @ 2021-06-29 10:09:23,921
Scheduler has been shut down @ 2021-06-29 10:09:23,921
Exiting immediately! @ 2021-06-29 10:09:25,289
Scheduler started @ 2021-06-29 10:10:44,887
Received signal 2 (SIGINT), stopping... @ 2021-06-29 10:11:42,161
Scheduler has been shut down @ 2021-06-29 10:11:42,162
Scheduler started @ 2021-06-29 10:23:42,760
Scheduler started @ 2021-06-29 18:16:38,100
Received signal 2 (SIGINT), stopping... @ 2021-06-29 18:22:50,991
Scheduler has been shut down @ 2021-06-29 18:22:50,991
Exiting immediately! @ 2021-06-29 18:22:58,807
Scheduler started @ 2021-06-29 18:23:04,814
Received signal 2 (SIGINT), stopping... @ 2021-06-29 18:29:47,845
Scheduler has been shut down @ 2021-06-29 18:29:47,845
Scheduler started @ 2021-06-29 18:41:50,642
No error handlers are registered, logging exception. @ 2021-06-29 18:42:03,513
Traceback (most recent call last):
  File "C:\Users\Vincent\AppData\Local\Programs\Python\Python39\lib\site-packages\telegram\ext\dispatcher.py", line 442, in process_update
    handler.handle_update(update, self, check, context)
  File "C:\Users\Vincent\AppData\Local\Programs\Python\Python39\lib\site-packages\telegram\ext\handler.py", line 160, in handle_update
    return self.callback(update, context)
TypeError: echo() takes 2 positional arguments but 3 were given
No error handlers are registered, logging exception. @ 2021-06-29 18:42:26,304
Traceback (most recent call last):
  File "C:\Users\Vincent\AppData\Local\Programs\Python\Python39\lib\site-packages\telegram\ext\dispatcher.py", line 442, in process_update
    handler.handle_update(update, self, check, context)
  File "C:\Users\Vincent\AppData\Local\Programs\Python\Python39\lib\site-packages\telegram\ext\handler.py", line 160, in handle_update
    return self.callback(update, context)
TypeError: echo() takes 2 positional arguments but 3 were given
Received signal 2 (SIGINT), stopping... @ 2021-06-29 18:44:04,044
Scheduler has been shut down @ 2021-06-29 18:44:04,044
Exiting immediately! @ 2021-06-29 18:44:08,065
Scheduler started @ 2021-06-29 18:44:10,111
No error handlers are registered, logging exception. @ 2021-06-29 18:44:13,608
Traceback (most recent call last):
  File "C:\Users\Vincent\AppData\Local\Programs\Python\Python39\lib\site-packages\telegram\ext\dispatcher.py", line 442, in process_update
    handler.handle_update(update, self, check, context)
  File "C:\Users\Vincent\AppData\Local\Programs\Python\Python39\lib\site-packages\telegram\ext\handler.py", line 160, in handle_update
    return self.callback(update, context)
  File "C:\Users\Vincent\Documents\GitHub\cloudRPC\Cloud_Prototype\tg.py", line 27, in echo
    keyboard = [[InlineKeyboardButton("Option 1", callback_data='1'),InlineKeyboardButton("Option 2", callback_data='2')], [InlineKeyboardButton("Option 3", callback_data='3')]]
NameError: name 'InlineKeyboardButton' is not defined
Received signal 2 (SIGINT), stopping... @ 2021-06-29 18:47:01,054
Scheduler has been shut down @ 2021-06-29 18:47:01,055
Exiting immediately! @ 2021-06-29 18:47:07,075
Scheduler started @ 2021-06-29 18:49:26,270
No error handlers are registered, logging exception. @ 2021-06-29 18:49:29,209
Traceback (most recent call last):
  File "C:\Users\Vincent\AppData\Local\Programs\Python\Python39\lib\site-packages\telegram\ext\dispatcher.py", line 442, in process_update
    handler.handle_update(update, self, check, context)
  File "C:\Users\Vincent\AppData\Local\Programs\Python\Python39\lib\site-packages\telegram\ext\handler.py", line 160, in handle_update
    return self.callback(update, context)
  File "C:\Users\Vincent\Documents\GitHub\cloudRPC\Cloud_Prototype\tg.py", line 27, in echo
    keyboard = [[InlineKeyboardButton("Option 1", callback_data='1'),InlineKeyboardButton("Option 2", callback_data='2')], [InlineKeyboardButton("Option 3", callback_data='3')]]
NameError: name 'InlineKeyboardButton' is not defined
Received signal 2 (SIGINT), stopping... @ 2021-06-29 18:51:03,564
Scheduler has been shut down @ 2021-06-29 18:51:03,564
Scheduler started @ 2021-06-29 21:44:33,380
Received signal 2 (SIGINT), stopping... @ 2021-06-29 21:47:05,936
Scheduler has been shut down @ 2021-06-29 21:47:05,936
Scheduler started @ 2021-06-29 21:47:10,306
No error handlers are registered, logging exception. @ 2021-06-29 21:47:15,379
Traceback (most recent call last):
  File "C:\Users\Vincent\AppData\Local\Programs\Python\Python39\lib\site-packages\telegram\ext\dispatcher.py", line 442, in process_update
    handler.handle_update(update, self, check, context)
  File "C:\Users\Vincent\AppData\Local\Programs\Python\Python39\lib\site-packages\telegram\ext\handler.py", line 160, in handle_update
    return self.callback(update, context)
  File "C:\Users\Vincent\Documents\GitHub\cloudRPC\Cloud_Prototype\tg.py", line 27, in echo
    keyboard = [[InlineKeyboardButton("Option 1", callback_data='1'),InlineKeyboardButton("Option 2", callback_data='2')], [InlineKeyboardButton("Option 3", callback_data='3')]]
NameError: name 'InlineKeyboardButton' is not defined
Received signal 2 (SIGINT), stopping... @ 2021-06-29 21:50:20,248
Scheduler has been shut down @ 2021-06-29 21:50:20,248
Exiting immediately! @ 2021-06-29 21:50:23,186
Scheduler started @ 2021-06-29 21:51:57,978
Received signal 2 (SIGINT), stopping... @ 2021-06-29 21:52:47,187
Scheduler has been shut down @ 2021-06-29 21:52:47,187
Exiting immediately! @ 2021-06-29 21:52:49,857
Scheduler started @ 2021-06-29 21:52:51,737
Received signal 2 (SIGINT), stopping... @ 2021-06-29 21:56:26,528
Scheduler has been shut down @ 2021-06-29 21:56:26,528
Exiting immediately! @ 2021-06-29 21:56:36,143
Scheduler started @ 2021-06-29 21:56:38,426
Received signal 2 (SIGINT), stopping... @ 2021-06-29 22:01:07,566
Scheduler has been shut down @ 2021-06-29 22:01:07,567
Scheduler started @ 2021-06-29 22:03:11,883
Received signal 2 (SIGINT), stopping... @ 2021-06-29 22:12:17,420
Scheduler has been shut down @ 2021-06-29 22:12:17,420
Exiting immediately! @ 2021-06-29 22:12:26,029
Scheduler started @ 2021-06-29 22:12:28,318
Received signal 2 (SIGINT), stopping... @ 2021-06-29 23:18:25,697
Scheduler has been shut down @ 2021-06-29 23:18:25,697
Exiting immediately! @ 2021-06-29 23:18:33,115
Scheduler started @ 2021-06-29 23:18:35,628
